<?xml version='1.0'?>
<sdf version='1.4'>
  <model name="my_robot">
  <static>false</static>

  <link name='chassis'>
    <pose>0 0 .185 0 0 0</pose>

    <collision name='collision'>
      <geometry>
        <box>
          <size>1 .8 .3</size>
        </box>
      </geometry>
    </collision>
    <visual name='visual'>
    <pose>0 0 0.05 0 0 0</pose>
      <geometry>
        <box>
          <size>1 .8 .3</size>
        </box>
        <!-- <mesh>
          <uri>model://pioneer2dx/meshes/chassis.dae</uri>
          <scale>3 3 1.5</scale>
        </mesh> -->
      </geometry>
    </visual>
    
    <collision name='caster_collision_TL'>
      <pose>.45 .35 -0.135 0 0 0</pose>
      <geometry>
	      <sphere>
	        <radius>.05</radius>
        </sphere>
      </geometry>
      <surface>
        <friction>
	        <ode>
    	      <mu>0</mu>
            <mu2>0</mu2>
            <slip1>1.0</slip1>
            <slip2>1.0</slip2>
	        </ode>
        </friction>
      </surface>
    </collision>
    <visual name='caster_visual_TL'>
      <pose>.45 .35 -0.135 0 0 0</pose>
      <geometry>
        <sphere>
	        <radius>.05</radius>
        </sphere>
      </geometry>
    </visual>

    <collision name='caster_collision_TR'>
      <pose>.45 -.35 -0.135 0 0 0</pose>
      <geometry>
	      <sphere>
	        <radius>.05</radius>
        </sphere>
      </geometry>
      <surface>
        <friction>
	        <ode>
    	      <mu>0</mu>
            <mu2>0</mu2>
            <slip1>1.0</slip1>
            <slip2>1.0</slip2>
	        </ode>
        </friction>
      </surface>
    </collision>
    <visual name='caster_visual_TR'>
      <pose>.45 -.35 -0.135 0 0 0</pose>
      <geometry>
        <sphere>
	        <radius>.05</radius>
        </sphere>
      </geometry>
    </visual>

    <collision name='caster_collision_BL'>
      <pose>-.45 .35 -0.135 0 0 0</pose>
      <geometry>
	      <sphere>
	        <radius>.05</radius>
        </sphere>
      </geometry>
      <surface>
        <friction>
	        <ode>
    	      <mu>0</mu>
            <mu2>0</mu2>
            <slip1>1.0</slip1>
            <slip2>1.0</slip2>
	        </ode>
        </friction>
      </surface>
    </collision>
    <visual name='caster_visual_BL'>
      <pose>-.45 .35 -0.135 0 0 0</pose>
      <geometry>
        <sphere>
	        <radius>.05</radius>
        </sphere>
      </geometry>
    </visual>

    <collision name='caster_collision_BR'>
      <pose>-.45 -.35 -0.135 0 0 0</pose>
      <geometry>
	      <sphere>
	        <radius>.05</radius>
        </sphere>
      </geometry>
      <surface>
        <friction>
	        <ode>
    	      <mu>0</mu>
            <mu2>0</mu2>
            <slip1>1.0</slip1>
            <slip2>1.0</slip2>
	        </ode>
        </friction>
      </surface>
    </collision>
    <visual name='caster_visual_BR'>
      <pose>-.45 -.35 -0.135 0 0 0</pose>
      <geometry>
        <sphere>
	        <radius>.05</radius>
        </sphere>
      </geometry>
    </visual>

  </link>

  <link name="left_wheel">
    <pose>0 0.38 0.075 0 1.5707 1.5707</pose>
    <collision name="collision">
      <geometry>
        <cylinder>
          <radius>.075</radius>
          <length>.05</length>
        </cylinder>
      </geometry>
    </collision>
    <visual name="visual">
      <geometry>
        <cylinder>
          <radius>.075</radius>
          <length>.05</length>
        </cylinder>
      </geometry>
    </visual>
  </link>

  <link name="right_wheel">
    <pose>0 -0.38 0.075 0 1.5707 1.5707</pose>
    <collision name="collision">
      <geometry>
        <cylinder>
          <radius>.075</radius>
          <length>.05</length>
        </cylinder>
      </geometry>
    </collision>
    <visual name="visual">
      <geometry>
        <cylinder>
          <radius>.075</radius>
          <length>.05</length>
        </cylinder>
      </geometry>
    </visual>
  </link>

  <joint type="revolute" name="left_wheel_hinge">
    <pose>0 0 0 0 0 0</pose>
    <child>left_wheel</child>
    <parent>chassis</parent>
    <axis>
      <xyz>0 1 0</xyz>
    </axis>
  </joint>

  <joint type="revolute" name="right_wheel_hinge">
    <pose>0 0 0 0 0 0</pose>
    <child>right_wheel</child>
    <parent>chassis</parent>
    <axis>
      <xyz>0 1 0</xyz>
    </axis>
  </joint>

  <include>
    <uri>model://hokuyo</uri>
    <pose>0.45 0 0.4 0 0 0</pose>
  </include>
  <joint type="fixed" name="hokuyo_joint">
    <child>hokuyo::link</child>
    <parent>chassis</parent>
  </joint>

  <include>
    <uri>model://camera</uri>
    <pose>0.5 0 0.15 0 -0.25 0</pose>
  </include>
  <joint type="fixed" name="camera_joint">
    <child>camera::link</child>
    <parent>chassis</parent>
  </joint>

  </model>
</sdf>
